2022-03-22 06:10:06,913 -  nornir.core -     INFO -        run() - Running task 'load_vars' with args {} on 10 hosts
2022-03-22 06:10:06,928 -  nornir.core -     INFO -        run() - Running task 'replace_config' with args {} on 10 hosts
2022-03-22 06:10:07,015 - nornir.core.task -    ERROR -      start() - Host 'CSR2': task 'template_file' failed with traceback:
Traceback (most recent call last):
  File "/home/geordie/.local/lib/python3.8/site-packages/nornir/core/task.py", line 99, in start
    r = self.task(self, **self.params)
  File "/home/geordie/.local/lib/python3.8/site-packages/nornir_jinja2/plugins/tasks/template_file.py", line 42, in template_file
    t = env.get_template(template)
  File "/home/geordie/.local/lib/python3.8/site-packages/jinja2/environment.py", line 997, in get_template
    return self._load_template(name, globals)
  File "/home/geordie/.local/lib/python3.8/site-packages/jinja2/environment.py", line 958, in _load_template
    template = self.loader.load(self, name, self.make_globals(globals))
  File "/home/geordie/.local/lib/python3.8/site-packages/jinja2/loaders.py", line 125, in load
    source, filename, uptodate = self.get_source(environment, name)
  File "/home/geordie/.local/lib/python3.8/site-packages/jinja2/loaders.py", line 214, in get_source
    raise TemplateNotFound(template)
jinja2.exceptions.TemplateNotFound: CSR2.j2

2022-03-22 06:10:07,020 - nornir.core.task -    ERROR -      start() - Host 'CSR2': task 'replace_config' failed with traceback:
Traceback (most recent call last):
  File "/home/geordie/.local/lib/python3.8/site-packages/nornir/core/task.py", line 99, in start
    r = self.task(self, **self.params)
  File "replace.py", line 16, in replace_config
    template_results = task.run(
  File "/home/geordie/.local/lib/python3.8/site-packages/nornir/core/task.py", line 174, in run
    raise NornirSubTaskError(task=run_task, result=r)
nornir.core.exceptions.NornirSubTaskError: Subtask: template_file (failed)


2022-03-22 06:10:07,450 - nornir.core.task -    ERROR -      start() - Host 'R7': task 'napalm_configure' failed with traceback:
Traceback (most recent call last):
  File "/home/geordie/.local/lib/python3.8/site-packages/nornir/core/task.py", line 99, in start
    r = self.task(self, **self.params)
  File "/home/geordie/.local/lib/python3.8/site-packages/nornir_napalm/plugins/tasks/napalm_configure.py", line 29, in napalm_configure
    device = task.host.get_connection(CONNECTION_NAME, task.nornir.config)
  File "/home/geordie/.local/lib/python3.8/site-packages/nornir/core/inventory.py", line 494, in get_connection
    self.open_connection(
  File "/home/geordie/.local/lib/python3.8/site-packages/nornir/core/inventory.py", line 546, in open_connection
    conn_obj.open(
  File "/home/geordie/.local/lib/python3.8/site-packages/nornir_napalm/plugins/connections/__init__.py", line 57, in open
    connection.open()
  File "/home/geordie/.local/lib/python3.8/site-packages/napalm/ios/ios.py", line 169, in open
    self.device = self._netmiko_open(
  File "/home/geordie/.local/lib/python3.8/site-packages/napalm/base/base.py", line 86, in _netmiko_open
    self._netmiko_device = ConnectHandler(
  File "/home/geordie/.local/lib/python3.8/site-packages/netmiko/ssh_dispatcher.py", line 326, in ConnectHandler
    return ConnectionClass(*args, **kwargs)
  File "/home/geordie/.local/lib/python3.8/site-packages/netmiko/cisco/cisco_ios.py", line 17, in __init__
    return super().__init__(*args, **kwargs)
  File "/home/geordie/.local/lib/python3.8/site-packages/netmiko/base_connection.py", line 350, in __init__
    self._open()
  File "/home/geordie/.local/lib/python3.8/site-packages/netmiko/base_connection.py", line 355, in _open
    self.establish_connection()
  File "/home/geordie/.local/lib/python3.8/site-packages/netmiko/base_connection.py", line 935, in establish_connection
    self.remote_conn_pre.connect(**ssh_connect_params)
  File "/home/geordie/.local/lib/python3.8/site-packages/paramiko/client.py", line 435, in connect
    self._auth(
  File "/home/geordie/.local/lib/python3.8/site-packages/paramiko/client.py", line 767, in _auth
    raise SSHException("No authentication methods available")
paramiko.ssh_exception.SSHException: No authentication methods available

2022-03-22 06:10:07,451 - nornir.core.task -    ERROR -      start() - Host 'R7': task 'replace_config' failed with traceback:
Traceback (most recent call last):
  File "/home/geordie/.local/lib/python3.8/site-packages/nornir/core/task.py", line 99, in start
    r = self.task(self, **self.params)
  File "replace.py", line 21, in replace_config
    task.run(task=napalm_configure, configuration=configuration, replace=True)
  File "/home/geordie/.local/lib/python3.8/site-packages/nornir/core/task.py", line 174, in run
    raise NornirSubTaskError(task=run_task, result=r)
nornir.core.exceptions.NornirSubTaskError: Subtask: napalm_configure (failed)


2022-03-22 06:10:07,452 - nornir.core.task -    ERROR -      start() - Host 'R6': task 'napalm_configure' failed with traceback:
Traceback (most recent call last):
  File "/home/geordie/.local/lib/python3.8/site-packages/nornir/core/task.py", line 99, in start
    r = self.task(self, **self.params)
  File "/home/geordie/.local/lib/python3.8/site-packages/nornir_napalm/plugins/tasks/napalm_configure.py", line 29, in napalm_configure
    device = task.host.get_connection(CONNECTION_NAME, task.nornir.config)
  File "/home/geordie/.local/lib/python3.8/site-packages/nornir/core/inventory.py", line 494, in get_connection
    self.open_connection(
  File "/home/geordie/.local/lib/python3.8/site-packages/nornir/core/inventory.py", line 546, in open_connection
    conn_obj.open(
  File "/home/geordie/.local/lib/python3.8/site-packages/nornir_napalm/plugins/connections/__init__.py", line 57, in open
    connection.open()
  File "/home/geordie/.local/lib/python3.8/site-packages/napalm/ios/ios.py", line 169, in open
    self.device = self._netmiko_open(
  File "/home/geordie/.local/lib/python3.8/site-packages/napalm/base/base.py", line 86, in _netmiko_open
    self._netmiko_device = ConnectHandler(
  File "/home/geordie/.local/lib/python3.8/site-packages/netmiko/ssh_dispatcher.py", line 326, in ConnectHandler
    return ConnectionClass(*args, **kwargs)
  File "/home/geordie/.local/lib/python3.8/site-packages/netmiko/cisco/cisco_ios.py", line 17, in __init__
    return super().__init__(*args, **kwargs)
  File "/home/geordie/.local/lib/python3.8/site-packages/netmiko/base_connection.py", line 350, in __init__
    self._open()
  File "/home/geordie/.local/lib/python3.8/site-packages/netmiko/base_connection.py", line 355, in _open
    self.establish_connection()
  File "/home/geordie/.local/lib/python3.8/site-packages/netmiko/base_connection.py", line 935, in establish_connection
    self.remote_conn_pre.connect(**ssh_connect_params)
  File "/home/geordie/.local/lib/python3.8/site-packages/paramiko/client.py", line 435, in connect
    self._auth(
  File "/home/geordie/.local/lib/python3.8/site-packages/paramiko/client.py", line 767, in _auth
    raise SSHException("No authentication methods available")
paramiko.ssh_exception.SSHException: No authentication methods available

2022-03-22 06:10:07,452 - nornir.core.task -    ERROR -      start() - Host 'R2': task 'napalm_configure' failed with traceback:
Traceback (most recent call last):
  File "/home/geordie/.local/lib/python3.8/site-packages/nornir/core/task.py", line 99, in start
    r = self.task(self, **self.params)
  File "/home/geordie/.local/lib/python3.8/site-packages/nornir_napalm/plugins/tasks/napalm_configure.py", line 29, in napalm_configure
    device = task.host.get_connection(CONNECTION_NAME, task.nornir.config)
  File "/home/geordie/.local/lib/python3.8/site-packages/nornir/core/inventory.py", line 494, in get_connection
    self.open_connection(
  File "/home/geordie/.local/lib/python3.8/site-packages/nornir/core/inventory.py", line 546, in open_connection
    conn_obj.open(
  File "/home/geordie/.local/lib/python3.8/site-packages/nornir_napalm/plugins/connections/__init__.py", line 57, in open
    connection.open()
  File "/home/geordie/.local/lib/python3.8/site-packages/napalm/ios/ios.py", line 169, in open
    self.device = self._netmiko_open(
  File "/home/geordie/.local/lib/python3.8/site-packages/napalm/base/base.py", line 86, in _netmiko_open
    self._netmiko_device = ConnectHandler(
  File "/home/geordie/.local/lib/python3.8/site-packages/netmiko/ssh_dispatcher.py", line 326, in ConnectHandler
    return ConnectionClass(*args, **kwargs)
  File "/home/geordie/.local/lib/python3.8/site-packages/netmiko/cisco/cisco_ios.py", line 17, in __init__
    return super().__init__(*args, **kwargs)
  File "/home/geordie/.local/lib/python3.8/site-packages/netmiko/base_connection.py", line 350, in __init__
    self._open()
  File "/home/geordie/.local/lib/python3.8/site-packages/netmiko/base_connection.py", line 355, in _open
    self.establish_connection()
  File "/home/geordie/.local/lib/python3.8/site-packages/netmiko/base_connection.py", line 935, in establish_connection
    self.remote_conn_pre.connect(**ssh_connect_params)
  File "/home/geordie/.local/lib/python3.8/site-packages/paramiko/client.py", line 435, in connect
    self._auth(
  File "/home/geordie/.local/lib/python3.8/site-packages/paramiko/client.py", line 767, in _auth
    raise SSHException("No authentication methods available")
paramiko.ssh_exception.SSHException: No authentication methods available

2022-03-22 06:10:07,454 - nornir.core.task -    ERROR -      start() - Host 'R6': task 'replace_config' failed with traceback:
Traceback (most recent call last):
  File "/home/geordie/.local/lib/python3.8/site-packages/nornir/core/task.py", line 99, in start
    r = self.task(self, **self.params)
  File "replace.py", line 21, in replace_config
    task.run(task=napalm_configure, configuration=configuration, replace=True)
  File "/home/geordie/.local/lib/python3.8/site-packages/nornir/core/task.py", line 174, in run
    raise NornirSubTaskError(task=run_task, result=r)
nornir.core.exceptions.NornirSubTaskError: Subtask: napalm_configure (failed)


2022-03-22 06:10:07,455 - nornir.core.task -    ERROR -      start() - Host 'R2': task 'replace_config' failed with traceback:
Traceback (most recent call last):
  File "/home/geordie/.local/lib/python3.8/site-packages/nornir/core/task.py", line 99, in start
    r = self.task(self, **self.params)
  File "replace.py", line 21, in replace_config
    task.run(task=napalm_configure, configuration=configuration, replace=True)
  File "/home/geordie/.local/lib/python3.8/site-packages/nornir/core/task.py", line 174, in run
    raise NornirSubTaskError(task=run_task, result=r)
nornir.core.exceptions.NornirSubTaskError: Subtask: napalm_configure (failed)


2022-03-22 06:10:07,455 - nornir.core.task -    ERROR -      start() - Host 'CSR1': task 'napalm_configure' failed with traceback:
Traceback (most recent call last):
  File "/home/geordie/.local/lib/python3.8/site-packages/nornir/core/task.py", line 99, in start
    r = self.task(self, **self.params)
  File "/home/geordie/.local/lib/python3.8/site-packages/nornir_napalm/plugins/tasks/napalm_configure.py", line 29, in napalm_configure
    device = task.host.get_connection(CONNECTION_NAME, task.nornir.config)
  File "/home/geordie/.local/lib/python3.8/site-packages/nornir/core/inventory.py", line 494, in get_connection
    self.open_connection(
  File "/home/geordie/.local/lib/python3.8/site-packages/nornir/core/inventory.py", line 546, in open_connection
    conn_obj.open(
  File "/home/geordie/.local/lib/python3.8/site-packages/nornir_napalm/plugins/connections/__init__.py", line 57, in open
    connection.open()
  File "/home/geordie/.local/lib/python3.8/site-packages/napalm/ios/ios.py", line 169, in open
    self.device = self._netmiko_open(
  File "/home/geordie/.local/lib/python3.8/site-packages/napalm/base/base.py", line 86, in _netmiko_open
    self._netmiko_device = ConnectHandler(
  File "/home/geordie/.local/lib/python3.8/site-packages/netmiko/ssh_dispatcher.py", line 326, in ConnectHandler
    return ConnectionClass(*args, **kwargs)
  File "/home/geordie/.local/lib/python3.8/site-packages/netmiko/cisco/cisco_ios.py", line 17, in __init__
    return super().__init__(*args, **kwargs)
  File "/home/geordie/.local/lib/python3.8/site-packages/netmiko/base_connection.py", line 350, in __init__
    self._open()
  File "/home/geordie/.local/lib/python3.8/site-packages/netmiko/base_connection.py", line 355, in _open
    self.establish_connection()
  File "/home/geordie/.local/lib/python3.8/site-packages/netmiko/base_connection.py", line 935, in establish_connection
    self.remote_conn_pre.connect(**ssh_connect_params)
  File "/home/geordie/.local/lib/python3.8/site-packages/paramiko/client.py", line 435, in connect
    self._auth(
  File "/home/geordie/.local/lib/python3.8/site-packages/paramiko/client.py", line 767, in _auth
    raise SSHException("No authentication methods available")
paramiko.ssh_exception.SSHException: No authentication methods available

2022-03-22 06:10:07,459 - nornir.core.task -    ERROR -      start() - Host 'R1': task 'napalm_configure' failed with traceback:
Traceback (most recent call last):
  File "/home/geordie/.local/lib/python3.8/site-packages/nornir/core/task.py", line 99, in start
    r = self.task(self, **self.params)
  File "/home/geordie/.local/lib/python3.8/site-packages/nornir_napalm/plugins/tasks/napalm_configure.py", line 29, in napalm_configure
    device = task.host.get_connection(CONNECTION_NAME, task.nornir.config)
  File "/home/geordie/.local/lib/python3.8/site-packages/nornir/core/inventory.py", line 494, in get_connection
    self.open_connection(
  File "/home/geordie/.local/lib/python3.8/site-packages/nornir/core/inventory.py", line 546, in open_connection
    conn_obj.open(
  File "/home/geordie/.local/lib/python3.8/site-packages/nornir_napalm/plugins/connections/__init__.py", line 57, in open
    connection.open()
  File "/home/geordie/.local/lib/python3.8/site-packages/napalm/ios/ios.py", line 169, in open
    self.device = self._netmiko_open(
  File "/home/geordie/.local/lib/python3.8/site-packages/napalm/base/base.py", line 86, in _netmiko_open
    self._netmiko_device = ConnectHandler(
  File "/home/geordie/.local/lib/python3.8/site-packages/netmiko/ssh_dispatcher.py", line 326, in ConnectHandler
    return ConnectionClass(*args, **kwargs)
  File "/home/geordie/.local/lib/python3.8/site-packages/netmiko/cisco/cisco_ios.py", line 17, in __init__
    return super().__init__(*args, **kwargs)
  File "/home/geordie/.local/lib/python3.8/site-packages/netmiko/base_connection.py", line 350, in __init__
    self._open()
  File "/home/geordie/.local/lib/python3.8/site-packages/netmiko/base_connection.py", line 355, in _open
    self.establish_connection()
  File "/home/geordie/.local/lib/python3.8/site-packages/netmiko/base_connection.py", line 935, in establish_connection
    self.remote_conn_pre.connect(**ssh_connect_params)
  File "/home/geordie/.local/lib/python3.8/site-packages/paramiko/client.py", line 435, in connect
    self._auth(
  File "/home/geordie/.local/lib/python3.8/site-packages/paramiko/client.py", line 767, in _auth
    raise SSHException("No authentication methods available")
paramiko.ssh_exception.SSHException: No authentication methods available

2022-03-22 06:10:07,459 - nornir.core.task -    ERROR -      start() - Host 'R1': task 'replace_config' failed with traceback:
Traceback (most recent call last):
  File "/home/geordie/.local/lib/python3.8/site-packages/nornir/core/task.py", line 99, in start
    r = self.task(self, **self.params)
  File "replace.py", line 21, in replace_config
    task.run(task=napalm_configure, configuration=configuration, replace=True)
  File "/home/geordie/.local/lib/python3.8/site-packages/nornir/core/task.py", line 174, in run
    raise NornirSubTaskError(task=run_task, result=r)
nornir.core.exceptions.NornirSubTaskError: Subtask: napalm_configure (failed)


2022-03-22 06:10:07,460 - nornir.core.task -    ERROR -      start() - Host 'R5': task 'napalm_configure' failed with traceback:
Traceback (most recent call last):
  File "/home/geordie/.local/lib/python3.8/site-packages/nornir/core/task.py", line 99, in start
    r = self.task(self, **self.params)
  File "/home/geordie/.local/lib/python3.8/site-packages/nornir_napalm/plugins/tasks/napalm_configure.py", line 29, in napalm_configure
    device = task.host.get_connection(CONNECTION_NAME, task.nornir.config)
  File "/home/geordie/.local/lib/python3.8/site-packages/nornir/core/inventory.py", line 494, in get_connection
    self.open_connection(
  File "/home/geordie/.local/lib/python3.8/site-packages/nornir/core/inventory.py", line 546, in open_connection
    conn_obj.open(
  File "/home/geordie/.local/lib/python3.8/site-packages/nornir_napalm/plugins/connections/__init__.py", line 57, in open
    connection.open()
  File "/home/geordie/.local/lib/python3.8/site-packages/napalm/ios/ios.py", line 169, in open
    self.device = self._netmiko_open(
  File "/home/geordie/.local/lib/python3.8/site-packages/napalm/base/base.py", line 86, in _netmiko_open
    self._netmiko_device = ConnectHandler(
  File "/home/geordie/.local/lib/python3.8/site-packages/netmiko/ssh_dispatcher.py", line 326, in ConnectHandler
    return ConnectionClass(*args, **kwargs)
  File "/home/geordie/.local/lib/python3.8/site-packages/netmiko/cisco/cisco_ios.py", line 17, in __init__
    return super().__init__(*args, **kwargs)
  File "/home/geordie/.local/lib/python3.8/site-packages/netmiko/base_connection.py", line 350, in __init__
    self._open()
  File "/home/geordie/.local/lib/python3.8/site-packages/netmiko/base_connection.py", line 355, in _open
    self.establish_connection()
  File "/home/geordie/.local/lib/python3.8/site-packages/netmiko/base_connection.py", line 935, in establish_connection
    self.remote_conn_pre.connect(**ssh_connect_params)
  File "/home/geordie/.local/lib/python3.8/site-packages/paramiko/client.py", line 435, in connect
    self._auth(
  File "/home/geordie/.local/lib/python3.8/site-packages/paramiko/client.py", line 767, in _auth
    raise SSHException("No authentication methods available")
paramiko.ssh_exception.SSHException: No authentication methods available

2022-03-22 06:10:07,461 - nornir.core.task -    ERROR -      start() - Host 'R5': task 'replace_config' failed with traceback:
Traceback (most recent call last):
  File "/home/geordie/.local/lib/python3.8/site-packages/nornir/core/task.py", line 99, in start
    r = self.task(self, **self.params)
  File "replace.py", line 21, in replace_config
    task.run(task=napalm_configure, configuration=configuration, replace=True)
  File "/home/geordie/.local/lib/python3.8/site-packages/nornir/core/task.py", line 174, in run
    raise NornirSubTaskError(task=run_task, result=r)
nornir.core.exceptions.NornirSubTaskError: Subtask: napalm_configure (failed)


2022-03-22 06:10:07,461 - nornir.core.task -    ERROR -      start() - Host 'R3': task 'napalm_configure' failed with traceback:
Traceback (most recent call last):
  File "/home/geordie/.local/lib/python3.8/site-packages/nornir/core/task.py", line 99, in start
    r = self.task(self, **self.params)
  File "/home/geordie/.local/lib/python3.8/site-packages/nornir_napalm/plugins/tasks/napalm_configure.py", line 29, in napalm_configure
    device = task.host.get_connection(CONNECTION_NAME, task.nornir.config)
  File "/home/geordie/.local/lib/python3.8/site-packages/nornir/core/inventory.py", line 494, in get_connection
    self.open_connection(
  File "/home/geordie/.local/lib/python3.8/site-packages/nornir/core/inventory.py", line 546, in open_connection
    conn_obj.open(
  File "/home/geordie/.local/lib/python3.8/site-packages/nornir_napalm/plugins/connections/__init__.py", line 57, in open
    connection.open()
  File "/home/geordie/.local/lib/python3.8/site-packages/napalm/ios/ios.py", line 169, in open
    self.device = self._netmiko_open(
  File "/home/geordie/.local/lib/python3.8/site-packages/napalm/base/base.py", line 86, in _netmiko_open
    self._netmiko_device = ConnectHandler(
  File "/home/geordie/.local/lib/python3.8/site-packages/netmiko/ssh_dispatcher.py", line 326, in ConnectHandler
    return ConnectionClass(*args, **kwargs)
  File "/home/geordie/.local/lib/python3.8/site-packages/netmiko/cisco/cisco_ios.py", line 17, in __init__
    return super().__init__(*args, **kwargs)
  File "/home/geordie/.local/lib/python3.8/site-packages/netmiko/base_connection.py", line 350, in __init__
    self._open()
  File "/home/geordie/.local/lib/python3.8/site-packages/netmiko/base_connection.py", line 355, in _open
    self.establish_connection()
  File "/home/geordie/.local/lib/python3.8/site-packages/netmiko/base_connection.py", line 935, in establish_connection
    self.remote_conn_pre.connect(**ssh_connect_params)
  File "/home/geordie/.local/lib/python3.8/site-packages/paramiko/client.py", line 435, in connect
    self._auth(
  File "/home/geordie/.local/lib/python3.8/site-packages/paramiko/client.py", line 767, in _auth
    raise SSHException("No authentication methods available")
paramiko.ssh_exception.SSHException: No authentication methods available

2022-03-22 06:10:07,461 - nornir.core.task -    ERROR -      start() - Host 'CSR1': task 'replace_config' failed with traceback:
Traceback (most recent call last):
  File "/home/geordie/.local/lib/python3.8/site-packages/nornir/core/task.py", line 99, in start
    r = self.task(self, **self.params)
  File "replace.py", line 21, in replace_config
    task.run(task=napalm_configure, configuration=configuration, replace=True)
  File "/home/geordie/.local/lib/python3.8/site-packages/nornir/core/task.py", line 174, in run
    raise NornirSubTaskError(task=run_task, result=r)
nornir.core.exceptions.NornirSubTaskError: Subtask: napalm_configure (failed)


2022-03-22 06:10:07,462 - nornir.core.task -    ERROR -      start() - Host 'R3': task 'replace_config' failed with traceback:
Traceback (most recent call last):
  File "/home/geordie/.local/lib/python3.8/site-packages/nornir/core/task.py", line 99, in start
    r = self.task(self, **self.params)
  File "replace.py", line 21, in replace_config
    task.run(task=napalm_configure, configuration=configuration, replace=True)
  File "/home/geordie/.local/lib/python3.8/site-packages/nornir/core/task.py", line 174, in run
    raise NornirSubTaskError(task=run_task, result=r)
nornir.core.exceptions.NornirSubTaskError: Subtask: napalm_configure (failed)


2022-03-22 06:10:07,463 - nornir.core.task -    ERROR -      start() - Host 'R8': task 'napalm_configure' failed with traceback:
Traceback (most recent call last):
  File "/home/geordie/.local/lib/python3.8/site-packages/nornir/core/task.py", line 99, in start
    r = self.task(self, **self.params)
  File "/home/geordie/.local/lib/python3.8/site-packages/nornir_napalm/plugins/tasks/napalm_configure.py", line 29, in napalm_configure
    device = task.host.get_connection(CONNECTION_NAME, task.nornir.config)
  File "/home/geordie/.local/lib/python3.8/site-packages/nornir/core/inventory.py", line 494, in get_connection
    self.open_connection(
  File "/home/geordie/.local/lib/python3.8/site-packages/nornir/core/inventory.py", line 546, in open_connection
    conn_obj.open(
  File "/home/geordie/.local/lib/python3.8/site-packages/nornir_napalm/plugins/connections/__init__.py", line 57, in open
    connection.open()
  File "/home/geordie/.local/lib/python3.8/site-packages/napalm/ios/ios.py", line 169, in open
    self.device = self._netmiko_open(
  File "/home/geordie/.local/lib/python3.8/site-packages/napalm/base/base.py", line 86, in _netmiko_open
    self._netmiko_device = ConnectHandler(
  File "/home/geordie/.local/lib/python3.8/site-packages/netmiko/ssh_dispatcher.py", line 326, in ConnectHandler
    return ConnectionClass(*args, **kwargs)
  File "/home/geordie/.local/lib/python3.8/site-packages/netmiko/cisco/cisco_ios.py", line 17, in __init__
    return super().__init__(*args, **kwargs)
  File "/home/geordie/.local/lib/python3.8/site-packages/netmiko/base_connection.py", line 350, in __init__
    self._open()
  File "/home/geordie/.local/lib/python3.8/site-packages/netmiko/base_connection.py", line 355, in _open
    self.establish_connection()
  File "/home/geordie/.local/lib/python3.8/site-packages/netmiko/base_connection.py", line 935, in establish_connection
    self.remote_conn_pre.connect(**ssh_connect_params)
  File "/home/geordie/.local/lib/python3.8/site-packages/paramiko/client.py", line 435, in connect
    self._auth(
  File "/home/geordie/.local/lib/python3.8/site-packages/paramiko/client.py", line 767, in _auth
    raise SSHException("No authentication methods available")
paramiko.ssh_exception.SSHException: No authentication methods available

2022-03-22 06:10:07,463 - nornir.core.task -    ERROR -      start() - Host 'R8': task 'replace_config' failed with traceback:
Traceback (most recent call last):
  File "/home/geordie/.local/lib/python3.8/site-packages/nornir/core/task.py", line 99, in start
    r = self.task(self, **self.params)
  File "replace.py", line 21, in replace_config
    task.run(task=napalm_configure, configuration=configuration, replace=True)
  File "/home/geordie/.local/lib/python3.8/site-packages/nornir/core/task.py", line 174, in run
    raise NornirSubTaskError(task=run_task, result=r)
nornir.core.exceptions.NornirSubTaskError: Subtask: napalm_configure (failed)


2022-03-22 06:10:07,531 - nornir.core.task -    ERROR -      start() - Host 'R4': task 'napalm_configure' failed with traceback:
Traceback (most recent call last):
  File "/home/geordie/.local/lib/python3.8/site-packages/nornir/core/task.py", line 99, in start
    r = self.task(self, **self.params)
  File "/home/geordie/.local/lib/python3.8/site-packages/nornir_napalm/plugins/tasks/napalm_configure.py", line 29, in napalm_configure
    device = task.host.get_connection(CONNECTION_NAME, task.nornir.config)
  File "/home/geordie/.local/lib/python3.8/site-packages/nornir/core/inventory.py", line 494, in get_connection
    self.open_connection(
  File "/home/geordie/.local/lib/python3.8/site-packages/nornir/core/inventory.py", line 546, in open_connection
    conn_obj.open(
  File "/home/geordie/.local/lib/python3.8/site-packages/nornir_napalm/plugins/connections/__init__.py", line 57, in open
    connection.open()
  File "/home/geordie/.local/lib/python3.8/site-packages/napalm/ios/ios.py", line 169, in open
    self.device = self._netmiko_open(
  File "/home/geordie/.local/lib/python3.8/site-packages/napalm/base/base.py", line 86, in _netmiko_open
    self._netmiko_device = ConnectHandler(
  File "/home/geordie/.local/lib/python3.8/site-packages/netmiko/ssh_dispatcher.py", line 326, in ConnectHandler
    return ConnectionClass(*args, **kwargs)
  File "/home/geordie/.local/lib/python3.8/site-packages/netmiko/cisco/cisco_ios.py", line 17, in __init__
    return super().__init__(*args, **kwargs)
  File "/home/geordie/.local/lib/python3.8/site-packages/netmiko/base_connection.py", line 350, in __init__
    self._open()
  File "/home/geordie/.local/lib/python3.8/site-packages/netmiko/base_connection.py", line 355, in _open
    self.establish_connection()
  File "/home/geordie/.local/lib/python3.8/site-packages/netmiko/base_connection.py", line 935, in establish_connection
    self.remote_conn_pre.connect(**ssh_connect_params)
  File "/home/geordie/.local/lib/python3.8/site-packages/paramiko/client.py", line 435, in connect
    self._auth(
  File "/home/geordie/.local/lib/python3.8/site-packages/paramiko/client.py", line 767, in _auth
    raise SSHException("No authentication methods available")
paramiko.ssh_exception.SSHException: No authentication methods available

2022-03-22 06:10:07,532 - nornir.core.task -    ERROR -      start() - Host 'R4': task 'replace_config' failed with traceback:
Traceback (most recent call last):
  File "/home/geordie/.local/lib/python3.8/site-packages/nornir/core/task.py", line 99, in start
    r = self.task(self, **self.params)
  File "replace.py", line 21, in replace_config
    task.run(task=napalm_configure, configuration=configuration, replace=True)
  File "/home/geordie/.local/lib/python3.8/site-packages/nornir/core/task.py", line 174, in run
    raise NornirSubTaskError(task=run_task, result=r)
nornir.core.exceptions.NornirSubTaskError: Subtask: napalm_configure (failed)


2022-03-22 06:12:08,341 -  nornir.core -     INFO -        run() - Running task 'load_vars' with args {} on 10 hosts
2022-03-22 06:12:08,363 -  nornir.core -     INFO -        run() - Running task 'replace_config' with args {} on 10 hosts
2022-03-22 06:12:08,428 - nornir.core.task -    ERROR -      start() - Host 'CSR2': task 'template_file' failed with traceback:
Traceback (most recent call last):
  File "/home/geordie/.local/lib/python3.8/site-packages/nornir/core/task.py", line 99, in start
    r = self.task(self, **self.params)
  File "/home/geordie/.local/lib/python3.8/site-packages/nornir_jinja2/plugins/tasks/template_file.py", line 42, in template_file
    t = env.get_template(template)
  File "/home/geordie/.local/lib/python3.8/site-packages/jinja2/environment.py", line 997, in get_template
    return self._load_template(name, globals)
  File "/home/geordie/.local/lib/python3.8/site-packages/jinja2/environment.py", line 958, in _load_template
    template = self.loader.load(self, name, self.make_globals(globals))
  File "/home/geordie/.local/lib/python3.8/site-packages/jinja2/loaders.py", line 125, in load
    source, filename, uptodate = self.get_source(environment, name)
  File "/home/geordie/.local/lib/python3.8/site-packages/jinja2/loaders.py", line 214, in get_source
    raise TemplateNotFound(template)
jinja2.exceptions.TemplateNotFound: CSR2.j2

2022-03-22 06:12:08,430 - nornir.core.task -    ERROR -      start() - Host 'CSR2': task 'replace_config' failed with traceback:
Traceback (most recent call last):
  File "/home/geordie/.local/lib/python3.8/site-packages/nornir/core/task.py", line 99, in start
    r = self.task(self, **self.params)
  File "replace.py", line 19, in replace_config
    template_results = task.run(
  File "/home/geordie/.local/lib/python3.8/site-packages/nornir/core/task.py", line 174, in run
    raise NornirSubTaskError(task=run_task, result=r)
nornir.core.exceptions.NornirSubTaskError: Subtask: template_file (failed)


2022-03-22 06:12:21,357 - nornir.core.task -    ERROR -      start() - Host 'R7': task 'napalm_configure' failed with traceback:
Traceback (most recent call last):
  File "/home/geordie/.local/lib/python3.8/site-packages/nornir/core/task.py", line 99, in start
    r = self.task(self, **self.params)
  File "/home/geordie/.local/lib/python3.8/site-packages/nornir_napalm/plugins/tasks/napalm_configure.py", line 39, in napalm_configure
    device.commit_config()
  File "/home/geordie/.local/lib/python3.8/site-packages/napalm/ios/ios.py", line 542, in commit_config
    raise ReplaceConfigException(msg)
napalm.base.exceptions.ReplaceConfigException: napalm-ios replace() requires Cisco 'archive' feature to be enabled.

2022-03-22 06:12:21,358 - nornir.core.task -    ERROR -      start() - Host 'R7': task 'replace_config' failed with traceback:
Traceback (most recent call last):
  File "/home/geordie/.local/lib/python3.8/site-packages/nornir/core/task.py", line 99, in start
    r = self.task(self, **self.params)
  File "replace.py", line 24, in replace_config
    task.run(task=napalm_configure, configuration=configuration, replace=True)
  File "/home/geordie/.local/lib/python3.8/site-packages/nornir/core/task.py", line 174, in run
    raise NornirSubTaskError(task=run_task, result=r)
nornir.core.exceptions.NornirSubTaskError: Subtask: napalm_configure (failed)


2022-03-22 06:12:22,686 - nornir.core.task -    ERROR -      start() - Host 'CSR1': task 'napalm_configure' failed with traceback:
Traceback (most recent call last):
  File "/home/geordie/.local/lib/python3.8/site-packages/nornir/core/task.py", line 99, in start
    r = self.task(self, **self.params)
  File "/home/geordie/.local/lib/python3.8/site-packages/nornir_napalm/plugins/tasks/napalm_configure.py", line 39, in napalm_configure
    device.commit_config()
  File "/home/geordie/.local/lib/python3.8/site-packages/napalm/ios/ios.py", line 531, in commit_config
    output = self._commit_handler(cmd)
  File "/home/geordie/.local/lib/python3.8/site-packages/napalm/ios/ios.py", line 470, in wrapper
    return f(self, *args, **kwargs)
  File "/home/geordie/.local/lib/python3.8/site-packages/napalm/ios/ios.py", line 487, in _commit_handler
    output = self.device.send_command_expect(cmd, expect_string=patterns)
  File "/home/geordie/.local/lib/python3.8/site-packages/netmiko/base_connection.py", line 1582, in send_command_expect
    return self.send_command(*args, **kwargs)
  File "/home/geordie/.local/lib/python3.8/site-packages/netmiko/utilities.py", line 500, in wrapper_decorator
    return func(self, *args, **kwargs)
  File "/home/geordie/.local/lib/python3.8/site-packages/netmiko/base_connection.py", line 1535, in send_command
    raise IOError(
OSError: Search pattern never detected in send_command: (?:[>##]\s*$|.*all username.*confirm)

2022-03-22 06:12:22,687 - nornir.core.task -    ERROR -      start() - Host 'CSR1': task 'replace_config' failed with traceback:
Traceback (most recent call last):
  File "/home/geordie/.local/lib/python3.8/site-packages/nornir/core/task.py", line 99, in start
    r = self.task(self, **self.params)
  File "replace.py", line 24, in replace_config
    task.run(task=napalm_configure, configuration=configuration, replace=True)
  File "/home/geordie/.local/lib/python3.8/site-packages/nornir/core/task.py", line 174, in run
    raise NornirSubTaskError(task=run_task, result=r)
nornir.core.exceptions.NornirSubTaskError: Subtask: napalm_configure (failed)


2022-03-22 06:12:23,435 - nornir.core.task -    ERROR -      start() - Host 'R6': task 'napalm_configure' failed with traceback:
Traceback (most recent call last):
  File "/home/geordie/.local/lib/python3.8/site-packages/nornir/core/task.py", line 99, in start
    r = self.task(self, **self.params)
  File "/home/geordie/.local/lib/python3.8/site-packages/nornir_napalm/plugins/tasks/napalm_configure.py", line 39, in napalm_configure
    device.commit_config()
  File "/home/geordie/.local/lib/python3.8/site-packages/napalm/ios/ios.py", line 542, in commit_config
    raise ReplaceConfigException(msg)
napalm.base.exceptions.ReplaceConfigException: napalm-ios replace() requires Cisco 'archive' feature to be enabled.

2022-03-22 06:12:23,435 - nornir.core.task -    ERROR -      start() - Host 'R6': task 'replace_config' failed with traceback:
Traceback (most recent call last):
  File "/home/geordie/.local/lib/python3.8/site-packages/nornir/core/task.py", line 99, in start
    r = self.task(self, **self.params)
  File "replace.py", line 24, in replace_config
    task.run(task=napalm_configure, configuration=configuration, replace=True)
  File "/home/geordie/.local/lib/python3.8/site-packages/nornir/core/task.py", line 174, in run
    raise NornirSubTaskError(task=run_task, result=r)
nornir.core.exceptions.NornirSubTaskError: Subtask: napalm_configure (failed)


2022-03-22 06:12:24,096 - nornir.core.task -    ERROR -      start() - Host 'R5': task 'napalm_configure' failed with traceback:
Traceback (most recent call last):
  File "/home/geordie/.local/lib/python3.8/site-packages/nornir/core/task.py", line 99, in start
    r = self.task(self, **self.params)
  File "/home/geordie/.local/lib/python3.8/site-packages/nornir_napalm/plugins/tasks/napalm_configure.py", line 39, in napalm_configure
    device.commit_config()
  File "/home/geordie/.local/lib/python3.8/site-packages/napalm/ios/ios.py", line 542, in commit_config
    raise ReplaceConfigException(msg)
napalm.base.exceptions.ReplaceConfigException: napalm-ios replace() requires Cisco 'archive' feature to be enabled.

2022-03-22 06:12:24,096 - nornir.core.task -    ERROR -      start() - Host 'R5': task 'replace_config' failed with traceback:
Traceback (most recent call last):
  File "/home/geordie/.local/lib/python3.8/site-packages/nornir/core/task.py", line 99, in start
    r = self.task(self, **self.params)
  File "replace.py", line 24, in replace_config
    task.run(task=napalm_configure, configuration=configuration, replace=True)
  File "/home/geordie/.local/lib/python3.8/site-packages/nornir/core/task.py", line 174, in run
    raise NornirSubTaskError(task=run_task, result=r)
nornir.core.exceptions.NornirSubTaskError: Subtask: napalm_configure (failed)


2022-03-22 06:12:25,360 - nornir.core.task -    ERROR -      start() - Host 'R8': task 'napalm_configure' failed with traceback:
Traceback (most recent call last):
  File "/home/geordie/.local/lib/python3.8/site-packages/nornir/core/task.py", line 99, in start
    r = self.task(self, **self.params)
  File "/home/geordie/.local/lib/python3.8/site-packages/nornir_napalm/plugins/tasks/napalm_configure.py", line 39, in napalm_configure
    device.commit_config()
  File "/home/geordie/.local/lib/python3.8/site-packages/napalm/ios/ios.py", line 542, in commit_config
    raise ReplaceConfigException(msg)
napalm.base.exceptions.ReplaceConfigException: napalm-ios replace() requires Cisco 'archive' feature to be enabled.

2022-03-22 06:12:25,361 - nornir.core.task -    ERROR -      start() - Host 'R8': task 'replace_config' failed with traceback:
Traceback (most recent call last):
  File "/home/geordie/.local/lib/python3.8/site-packages/nornir/core/task.py", line 99, in start
    r = self.task(self, **self.params)
  File "replace.py", line 24, in replace_config
    task.run(task=napalm_configure, configuration=configuration, replace=True)
  File "/home/geordie/.local/lib/python3.8/site-packages/nornir/core/task.py", line 174, in run
    raise NornirSubTaskError(task=run_task, result=r)
nornir.core.exceptions.NornirSubTaskError: Subtask: napalm_configure (failed)


2022-03-22 06:12:26,101 - nornir.core.task -    ERROR -      start() - Host 'R2': task 'napalm_configure' failed with traceback:
Traceback (most recent call last):
  File "/home/geordie/.local/lib/python3.8/site-packages/nornir/core/task.py", line 99, in start
    r = self.task(self, **self.params)
  File "/home/geordie/.local/lib/python3.8/site-packages/nornir_napalm/plugins/tasks/napalm_configure.py", line 39, in napalm_configure
    device.commit_config()
  File "/home/geordie/.local/lib/python3.8/site-packages/napalm/ios/ios.py", line 542, in commit_config
    raise ReplaceConfigException(msg)
napalm.base.exceptions.ReplaceConfigException: napalm-ios replace() requires Cisco 'archive' feature to be enabled.

2022-03-22 06:12:26,101 - nornir.core.task -    ERROR -      start() - Host 'R2': task 'replace_config' failed with traceback:
Traceback (most recent call last):
  File "/home/geordie/.local/lib/python3.8/site-packages/nornir/core/task.py", line 99, in start
    r = self.task(self, **self.params)
  File "replace.py", line 24, in replace_config
    task.run(task=napalm_configure, configuration=configuration, replace=True)
  File "/home/geordie/.local/lib/python3.8/site-packages/nornir/core/task.py", line 174, in run
    raise NornirSubTaskError(task=run_task, result=r)
nornir.core.exceptions.NornirSubTaskError: Subtask: napalm_configure (failed)


2022-03-22 06:12:33,629 - nornir.core.task -    ERROR -      start() - Host 'R1': task 'napalm_configure' failed with traceback:
Traceback (most recent call last):
  File "/home/geordie/.local/lib/python3.8/site-packages/nornir/core/task.py", line 99, in start
    r = self.task(self, **self.params)
  File "/home/geordie/.local/lib/python3.8/site-packages/nornir_napalm/plugins/tasks/napalm_configure.py", line 39, in napalm_configure
    device.commit_config()
  File "/home/geordie/.local/lib/python3.8/site-packages/napalm/ios/ios.py", line 531, in commit_config
    output = self._commit_handler(cmd)
  File "/home/geordie/.local/lib/python3.8/site-packages/napalm/ios/ios.py", line 470, in wrapper
    return f(self, *args, **kwargs)
  File "/home/geordie/.local/lib/python3.8/site-packages/napalm/ios/ios.py", line 487, in _commit_handler
    output = self.device.send_command_expect(cmd, expect_string=patterns)
  File "/home/geordie/.local/lib/python3.8/site-packages/netmiko/base_connection.py", line 1582, in send_command_expect
    return self.send_command(*args, **kwargs)
  File "/home/geordie/.local/lib/python3.8/site-packages/netmiko/utilities.py", line 500, in wrapper_decorator
    return func(self, *args, **kwargs)
  File "/home/geordie/.local/lib/python3.8/site-packages/netmiko/base_connection.py", line 1535, in send_command
    raise IOError(
OSError: Search pattern never detected in send_command: (?:[>##]\s*$|.*all username.*confirm)

2022-03-22 06:12:33,630 - nornir.core.task -    ERROR -      start() - Host 'R1': task 'replace_config' failed with traceback:
Traceback (most recent call last):
  File "/home/geordie/.local/lib/python3.8/site-packages/nornir/core/task.py", line 99, in start
    r = self.task(self, **self.params)
  File "replace.py", line 24, in replace_config
    task.run(task=napalm_configure, configuration=configuration, replace=True)
  File "/home/geordie/.local/lib/python3.8/site-packages/nornir/core/task.py", line 174, in run
    raise NornirSubTaskError(task=run_task, result=r)
nornir.core.exceptions.NornirSubTaskError: Subtask: napalm_configure (failed)


2022-03-22 06:12:34,683 - nornir.core.task -    ERROR -      start() - Host 'R3': task 'napalm_configure' failed with traceback:
Traceback (most recent call last):
  File "/home/geordie/.local/lib/python3.8/site-packages/nornir/core/task.py", line 99, in start
    r = self.task(self, **self.params)
  File "/home/geordie/.local/lib/python3.8/site-packages/nornir_napalm/plugins/tasks/napalm_configure.py", line 39, in napalm_configure
    device.commit_config()
  File "/home/geordie/.local/lib/python3.8/site-packages/napalm/ios/ios.py", line 531, in commit_config
    output = self._commit_handler(cmd)
  File "/home/geordie/.local/lib/python3.8/site-packages/napalm/ios/ios.py", line 470, in wrapper
    return f(self, *args, **kwargs)
  File "/home/geordie/.local/lib/python3.8/site-packages/napalm/ios/ios.py", line 487, in _commit_handler
    output = self.device.send_command_expect(cmd, expect_string=patterns)
  File "/home/geordie/.local/lib/python3.8/site-packages/netmiko/base_connection.py", line 1582, in send_command_expect
    return self.send_command(*args, **kwargs)
  File "/home/geordie/.local/lib/python3.8/site-packages/netmiko/utilities.py", line 500, in wrapper_decorator
    return func(self, *args, **kwargs)
  File "/home/geordie/.local/lib/python3.8/site-packages/netmiko/base_connection.py", line 1535, in send_command
    raise IOError(
OSError: Search pattern never detected in send_command: (?:[>##]\s*$|.*all username.*confirm)

2022-03-22 06:12:34,684 - nornir.core.task -    ERROR -      start() - Host 'R3': task 'replace_config' failed with traceback:
Traceback (most recent call last):
  File "/home/geordie/.local/lib/python3.8/site-packages/nornir/core/task.py", line 99, in start
    r = self.task(self, **self.params)
  File "replace.py", line 24, in replace_config
    task.run(task=napalm_configure, configuration=configuration, replace=True)
  File "/home/geordie/.local/lib/python3.8/site-packages/nornir/core/task.py", line 174, in run
    raise NornirSubTaskError(task=run_task, result=r)
nornir.core.exceptions.NornirSubTaskError: Subtask: napalm_configure (failed)


2022-03-22 06:12:48,744 - nornir.core.task -    ERROR -      start() - Host 'R4': task 'napalm_configure' failed with traceback:
Traceback (most recent call last):
  File "/home/geordie/.local/lib/python3.8/site-packages/nornir/core/task.py", line 99, in start
    r = self.task(self, **self.params)
  File "/home/geordie/.local/lib/python3.8/site-packages/nornir_napalm/plugins/tasks/napalm_configure.py", line 39, in napalm_configure
    device.commit_config()
  File "/home/geordie/.local/lib/python3.8/site-packages/napalm/ios/ios.py", line 531, in commit_config
    output = self._commit_handler(cmd)
  File "/home/geordie/.local/lib/python3.8/site-packages/napalm/ios/ios.py", line 470, in wrapper
    return f(self, *args, **kwargs)
  File "/home/geordie/.local/lib/python3.8/site-packages/napalm/ios/ios.py", line 487, in _commit_handler
    output = self.device.send_command_expect(cmd, expect_string=patterns)
  File "/home/geordie/.local/lib/python3.8/site-packages/netmiko/base_connection.py", line 1582, in send_command_expect
    return self.send_command(*args, **kwargs)
  File "/home/geordie/.local/lib/python3.8/site-packages/netmiko/utilities.py", line 500, in wrapper_decorator
    return func(self, *args, **kwargs)
  File "/home/geordie/.local/lib/python3.8/site-packages/netmiko/base_connection.py", line 1535, in send_command
    raise IOError(
OSError: Search pattern never detected in send_command: (?:[>##]\s*$|.*all username.*confirm)

2022-03-22 06:12:48,744 - nornir.core.task -    ERROR -      start() - Host 'R4': task 'replace_config' failed with traceback:
Traceback (most recent call last):
  File "/home/geordie/.local/lib/python3.8/site-packages/nornir/core/task.py", line 99, in start
    r = self.task(self, **self.params)
  File "replace.py", line 24, in replace_config
    task.run(task=napalm_configure, configuration=configuration, replace=True)
  File "/home/geordie/.local/lib/python3.8/site-packages/nornir/core/task.py", line 174, in run
    raise NornirSubTaskError(task=run_task, result=r)
nornir.core.exceptions.NornirSubTaskError: Subtask: napalm_configure (failed)


